Workbook

Sheet Materias Primas
A1: 📦 MATERIAS PRIMAS
A2: Insumo | B2: Presentación | C2: Precio ($) | D2: Unidad | E2: Precio/g o u ($)
A3: 🌾 HARINAS Y BASES
A4: Premezcla (casera) | B4: casera/5kg | C4: =((C6/10000)*1500+(C8/25000)*1500+(C7/10000)*2000+(C11/1000)*50)/5.05 -> 1681.1881 | D4: g | E4: =C4/1000 -> 1.6811881
A5: Premezcla Integral | B5: x kg | C5: 4000 | D5: g | E5: =C5/1000 -> 4
A6: Almidón/Harina de Mandioca | B6: x 10kg | C6: 23100 | D6: g | E6: =C6/10000 -> 2.31
A7: Almidón de Maíz | B7: x 10kg | C7: 14875 | D7: g | E7: =C7/10000 -> 1.4875
A8: Harina de Arroz | B8: x 25kg | C8: 25000 | D8: g | E8: =C8/25000 -> 1
A9: Harina de Almendras | B9: x kg | C9: 21685.6 | D9: g | E9: =C9/1000 -> 21.6856
A10: Harina de Coco | B10: x kg | C10: 5063.4 | D10: g | E10: =C10/1000 -> 5.0634
A11: Goma Xántica | B11: x kg | C11: 11000 | D11: g | E11: =C11/1000 -> 11
A12: Polenta (Harina de Maíz) | B12: x 730g | C12: 2200 | D12: g | E12: =C12/730 -> 3.0136986
A13: Puré de Papas Maggi | B13: x 200g | C13: 2200 | D13: g | E13: =C13/200 -> 11
A14: 🥛 LÁCTEOS Y HUEVOS
A15: Manteca | B15: x 2,5kg | C15: 29485.4 | D15: g | E15: =C15/2500 -> 11.79416
A16: Crema Ledevit | B16: x 4,7l | C16: 35750 | D16: ml | E16: =C16/4700 -> 7.606383
A17: Queso Tybo | B17: x kg | C17: 8675.5 | D17: g | E17: =C17/1000 -> 8.6755
A18: Queso Mantecoso | B18: x kg | C18: 6000 | D18: g | E18: =C18/1000 -> 6
A19: Queso Cremoso | B19: x kg | C19: 5899.9 | D19: g | E19: =C19/1000 -> 5.8999
A20: Huevos | B20: x 30 u | C20: 4500 | D20: u | E20: =C20/30 -> 150
A21: 🍬 AZÚCARES Y ENDULZANTES
A22: Azúcar | B22: x kg | C22: 1031.2 | D22: g | E22: =C22/1000 -> 1.0312
A23: Azúcar Mascabo | B23: x kg | C23: 1300 | D23: g | E23: =C23/1000 -> 1.3
A24: Sacarina | B24: x sobre | C24: 10 | D24: u | E24: =C24 -> 10
A25: Merengue en Polvo | B25: x kg | C25: 8000 | D25: g | E25: =C25/1000 -> 8
A26: 🍫 CHOCOLATES Y COBERTURAS
A27: Chocolate Semiamargo Coverlux | B27: x 800g | C27: 10600 | D27: g | E27: =C27/800 -> 13.25
A28: Chocolate s/azúcar | B28: x 800g | C28: 13000 | D28: g | E28: =C28/800 -> 16.25
A29: 🍯 RELLENOS Y CONSERVAS
A30: Dulce de Leche | B30: x 10kg | C30: 14625 | D30: g | E30: =C30/10000 -> 1.4625
A31: Dulce de Leche s/azúcar | B31: x 3kg | C31: 48000 | D31: g | E31: =C31/3000 -> 16
A32: Membrillo | B32: x 5kg | C32: 14897.6 | D32: g | E32: =C32/5000 -> 2.97952
A33: Membrillo s/azúcar | B33: x 200g | C33: 2700 | D33: g | E33: =C33/200 -> 13.5
A34: Duraznos en lata | B34: x lata | C34: 1800 | D34: u | E34: =C34 -> 1800
A35: 🍗 PROTEÍNAS
A36: Pollo | B36: x kg | C36: 9000 | D36: g | E36: =C36/1000 -> 9
A37: Jamón | B37: x kg | C37: 6298.1 | D37: g | E37: =C37/1000 -> 6.2981
A38: 🧂 ACEITES, CONDIMENTOS Y VARIOS
A39: Aceite | B39: x 1,5l | C39: 4852.8 | D39: ml | E39: =C39/1500 -> 3.2352
A40: Levadura | B40: x 500g | C40: 3200 | D40: g | E40: =C40/500 -> 6.4
...

Sheet Recetas y Márgenes
A1: RECETAS — COSTOS DINÁMICOS VINCULADOS A MATERIAS PRIMAS
A2: Ingrediente | B2: Cantidad | C2: Precio/g o u | D2: Costo ($) | E2: Costo x Unidad | F2: Precio Venta | G2: Margen Bruto
A3: 🍞 PAN DE MOLDE — 4 unidades
A4: Ingrediente | B4: Cantidad | C4: Precio/g o u | D4: Costo ($)
A5: Premezcla | B5: 1.700g | C5: ='Materias Primas'!C4/1000 -> 1.6811881 | D5: =('Materias Primas'!C4/1000)*1700 -> 2858.0198
A6: Levadura | B6: 140g | C6: ='Materias Primas'!C40/500 -> 6.4 | D6: =('Materias Primas'!C40/500)*140 -> 896
A7: Azúcar | B7: 100g | C7: ='Materias Primas'!C22/1000 -> 1.0312 | D7: =('Materias Primas'!C22/1000)*100 -> 103.12
A8: Aceite | B8: 100ml | C8: ='Materias Primas'!C39/1500 -> 3.2352 | D8: =('Materias Primas'!C39/1500)*100 -> 323.52
A9: Huevos | B9: 6 u | C9: ='Materias Primas'!C20/30 -> 150 | D9: =('Materias Primas'!C20/30)*6 -> 900
A10: ✅ PAN DE MOLDE | B10: 4 | D10: =SUM(D5:D9) -> 5080.6598 | E10: =D10/B10 -> 1270.165 | F10: 6000 | G10: =(F10-E10)/F10 -> 0.78830584
A12: 🥧 TARTAS DE ALMENDRAS S/A — 20 unidades
A13: Ingrediente | B13: Cantidad | C13: Precio/g o u | D13: Costo ($)
A14: Harina de Almendras | B14: 200g | C14: ='Materias Primas'!C9/1000 -> 21.6856 | D14: =('Materias Primas'!C9/1000)*200 -> 4337.12
A15: Harina de Coco | B15: 50g | C15: ='Materias Primas'!C10/1000 -> 5.0634 | D15: =('Materias Primas'!C10/1000)*50 -> 253.17
A16: Huevo | B16: 1 u | C16: ='Materias Primas'!C20/30 -> 150 | D16: =('Materias Primas'!C20/30)*1 -> 150
A17: Manteca | B17: 100g | C17: ='Materias Primas'!C15/2500 -> 11.79416 | D17: =('Materias Primas'!C15/2500)*100 -> 1179.416
A18: Sacarina | B18: 6 sobres | C18: ='Materias Primas'!C24 -> 10 | D18: ='Materias Primas'!C24*6 -> 60
A19: Esencia de Vainilla | B19: 10ml | C19: ='Materias Primas'!C42/2000 -> 2.9 | D19: =('Materias Primas'!C42/2000)*10 -> 29
A20: ✅ TARTAS ALMENDRAS S/A | B20: 20 | D20: =SUM(D14:D19) -> 6008.706 | E20: =D20/B20 -> 300.4353 | F20: 3000 | G20: =(F20-E20)/F20 -> 0.8998549
A22: 🥧 TARTAS SALADAS — 2 unidades
A23: Ingrediente | B23: Cantidad | C23: Precio/g o u | D23: Costo ($)
A24: Premezcla | B24: 280g | C24: ='Materias Primas'!C4/1000 -> 1.6811881 | D24: =('Materias Primas'!C4/1000)*280 -> 470.73267
A25: Huevo (masa) | B25: 1 u | C25: ='Materias Primas'!C20/30 -> 150 | D25: =('Materias Primas'!C20/30)*1 -> 150
A26: Aceite | B26: 20ml | C26: ='Materias Primas'!C39/1500 -> 3.2352 | D26: =('Materias Primas'!C39/1500)*20 -> 64.704
A27: Queso Mantecoso | B27: 50g | C27: ='Materias Primas'!C18/1000 -> 6 | D27: =('Materias Primas'!C18/1000)*50 -> 300
A28: Jamón | B28: 30g | C28: ='Materias Primas'!C37/1000 -> 6.2981 | D28: =('Materias Primas'!C37/1000)*30 -> 188.943
A29: Huevos relleno | B29: 2 u | C29: ='Materias Primas'!C20/30 -> 150 | D29: =('Materias Primas'!C20/30)*2 -> 300
A30: Relleno calabaza/acelga | B30: prop. | C30: =1500/6 -> 250 | D30: =1500/6*2 -> 500
A31: ✅ TARTAS SALADAS | B31: 2 | D31: =SUM(D24:D30) -> 1974.3797 | E31: =D31/B31 -> 987.18984 | F31: 8500 | G31: =(F31-E31)/F31 -> 0.88386002
A33: 🥟 EMPANADAS DE VERDURA — 12 unidades
A34: Ingrediente | B34: Cantidad | C34: Precio/g o u | D34: Costo ($)
A35: Tapas de empanada | B35: 12 u | C35: =3000/12 -> 250 | D35: =3000 -> 3000
A36: Acelga (50% del rinde) | B36: 1/2 | C36: =1500/2 -> 750 | D36: =750 -> 750
A37: Queso Tybo | B37: 30g | C37: ='Materias Primas'!C17/1000 -> 8.6755 | D37: =('Materias Primas'!C17/1000)*30 -> 260.265
A38: Queso Mantecoso | B38: 15g | C38: ='Materias Primas'!C18/1000 -> 6 | D38: =('Materias Primas'!C18/1000)*15 -> 90
A39: Cebolla | B39: 1/2 u | C39: =200/2 -> 100 | D39: =100 -> 100
A40: ✅ EMPANADAS | B40: 12 | D40: =SUM(D35:D39) -> 4200.265 | E40: =D40/B40 -> 350.02208 | F40: 1000 | G40: =(F40-E40)/F40 -> 0.64997792
A42: 🍕 PREPIZZA — 10 unidades
A43: Ingrediente | B43: Cantidad | C43: Precio/g o u | D43: Costo ($)
A44: Premezcla | B44: 1.700g | C44: ='Materias Primas'!C4/1000 -> 1.6811881 | D44: =('Materias Primas'!C4/1000)*1700 -> 2858.0198
...

Sheet Gastos Fijos
A1: 💼 GASTOS FIJOS — SEMANAL Y MENSUAL
A2: Editá las celdas en AMARILLO para actualizar los gastos. Los valores en azul se calculan automáticamente.
A3: Concepto | B3: Frecuencia | C3: Monto ($) | D3: Semanal ($) | E3: Mensual ($)
A4: 👷 PERSONAL
A5: Empleado | B5: 15.000/día x 5 días | C5: 15000 | D5: =C5*5 -> 75000 | E5: =D5*4 -> 300000
A6: Subtotal Personal | D6: =SUM(D5:D5) -> 75000 | E6: =SUM(E5:E5) -> 300000
A8: 🧴 CONSUMIBLES (uso general)
A9: Rocío Vegetal Natura 200ml | B9: 16u/mes (8u cada 15 días) | C9: 3327.9 | D9: =C9*4 -> 13311.6 | E9: =C9*16 -> 53246.4
A10: Subtotal Consumibles | D10: =SUM(D9:D9) -> 13311.6 | E10: =SUM(E9:E9) -> 53246.4
A11: 💡 SERVICIOS (mensuales)
A12: Electricidad | B12: Mensual | C12: 60000 | D12: =C12/4 -> 15000 | E12: =C12 -> 60000
A13: Gas | B13: Mensual | C13: 60000 | D13: =C13/4 -> 15000 | E13: =C13 -> 60000
A14: Agua | B14: Mensual | C14: 10000 | D14: =C14/4 -> 2500 | E14: =C14 -> 10000
A15: Subtotal Servicios | D15: =SUM(D12:D14) -> 32500 | E15: =SUM(E12:E14) -> 130000
A17: 📦 TOTAL GASTOS FIJOS | D17: =D6+D10+D15 -> 120811.6
A19: 📊 RESUMEN: GANANCIA NETA (ventas - costos - gastos)
A20: 💰 Ingreso semanal (ventas) | D20: ='Proyección Semanal'!F21 -> 1192000
A21: 💸 Costo semanal (ingredientes) | D21: ='Proyección Semanal'!D21 -> 304925.99
A22: 🔧 Gastos fijos semanales | D22: =D17 -> 120811.6
A23: 📈 Ganancia bruta semanal | D23: ='Proyección Semanal'!G21 -> 887074.01
A24: ✅ GANANCIA NETA SEMANAL | D24: =D23-D17 -> 766262.41
A25: 📅 Ganancia neta mensual (x4) | D25: =(D23-D17)*4 -> 3065049.6
A26: 📊 Margen neto semanal | D26: =IFERROR((D23-D17)/D20,0) -> 0.64283759
A27: ⚡ Tip: Modificá las celdas en AMARILLO para simular cambios en gastos o salarios.

Sheet Precios y Proveedores
A1: 📈 SEGUIMIENTO DE PRECIOS Y PROVEEDORES
A2: Registrá cada cambio de precio con fecha. El Excel calcula automáticamente la variación y te muestra el mejor proveedor actual.
A4: 📋 SECCIÓN 1 — HISTORIAL DE PRECIOS (completar cada vez que cambia el precio)
A5: Insumo | B5: Proveedor | C5: Fecha | D5: Presentación | E5: Precio ($) | F5: Precio/g ($) | G5: Var. vs anterior | H5: Var. % | I5: Nota
A6: Almidón/Harina de Mandioca | B6: Frenart | C6: 28/02/2026 | D6: 10 kg | E6: 23100 | F6: 2.31 | G6: — | H6: — | I6: Ticket 28/02/2026
A7: Almidón/Harina de Mandioca | B7: Proveedor anterior | C7: — | D7: 10 kg | E7: 17500 | F7: 1.75 | G7: — | H7: — | I7: Precio anterior
A8: Almidón de Maíz | B8: — | C8: 28/02/2026 | D8: 10 kg | E8: 14875 | F8: 1.488 | G8: — | H8: — | I8: Ticket 26/02/2026
A9: Harina de Arroz | B9: — | C9: 28/02/2026 | D9: 25 kg | E9: 25000 | F9: 1 | G9: — | H9: — | I9: Precio base
A10: Goma Xántica | B10: — | C10: 28/02/2026 | D10: 1 kg | E10: 11000 | F10: 11 | G10: — | H10: — | I10: Precio base
A11: Chocolate Semiamargo | B11: Coverlux | C11: 28/02/2026 | D11: 800 g | E11: 10600 | F11: 13.25 | G11: — | H11: — | I11: Ticket 28/02/2026
A12: Manteca | B12: — | C12: 28/02/2026 | D12: 2,5 kg | E12: 29485 | F12: 11.794 | G12: — | H12: — | I12: Ticket 26/02/2026
A13: Crema Ledevit | B13: Ledevit | C13: 28/02/2026 | D13: 4,7 l | E13: 35750 | F13: 7.606 | G13: — | H13: — | I13: Precio base
A14: Queso Cremoso | B14: — | C14: 28/02/2026 | D14: 1 kg | E14: 5900 | F14: 5.9 | G14: — | H14: — | I14: Ticket 26/02/2026
A15: Queso Tybo | B15: — | C15: 28/02/2026 | D15: 1 kg | E15: 8676 | F15: 8.676 | G15: — | H15: — | I15: Ticket 26/02/2026
A16: Dulce de Leche | B16: — | C16: 28/02/2026 | D16: 10 kg | E16: 14625 | F16: 1.462 | G16: — | H16: — | I16: Ticket 26/02/2026
A34: 🏆 SECCIÓN 2 — COMPARATIVA DE PROVEEDORES (mismo insumo, distintos precios)
A35: Insumo | B35: Presentación | C35: Proveedor 1 Precio ($) | D35: Proveedor 2 Precio ($) | E35: Proveedor 3 Precio ($) | F35: ✅ Más barato | G35: 💰 Ahorro vs actual ($) | H35: Ahorro % | I35: Acción
A36: Almidón/Harina de Mandioca | B36: 10 kg | C36: 23100 | F36: =IFERROR(MIN(C36,IF(D36<>"",D36,C36),IF(E36<>"",E36,C36)),"—") -> 23100 | G36: =IFERROR(C36-F36,"—") -> 0 | H36: =IFERROR((C36-F36)/C36,"—") -> 0 | I36: =IFERROR(IF(F36<C36,"⚡ Cambiar proveedor","✅ OK"),"—") -> ✅ OK
A37: Almidón de Maíz | B37: 10 kg | C37: 14875 | F37: =IFERROR(MIN(C37,IF(D37<>"",D37,C37),IF(E37<>"",E37,C37)),"—") -> 14875 | G37: =IFERROR(C37-F37,"—") -> 0 | H37: =IFERROR((C37-F37)/C37,"—") -> 0 | I37: =IFERROR(IF(F37<C37,"⚡ Cambiar proveedor","✅ OK"),"—") -> ✅ OK
A38: Chocolate Semiamargo | B38: 800 g | C38: 10600 | F38: =IFERROR(MIN(C38,IF(D38<>"",D38,C38),IF(E38<>"",E38,C38)),"—") -> 10600 | G38: =IFERROR(C38-F38,"—") -> 0 | H38: =IFERROR((C38-F38)/C38,"—") -> 0 | I38: =IFERROR(IF(F38<C38,"⚡ Cambiar proveedor","✅ OK"),"—") -> ✅ OK
A39: Manteca | B39: 2,5 kg | C39: 29485 | F39: =IFERROR(MIN(C39,IF(D39<>"",D39,C39),IF(E39<>"",E39,C39)),"—") -> 29485 | G39: =IFERROR(C39-F39,"—") -> 0 | H39: =IFERROR((C39-F39)/C39,"—") -> 0 | I39: =IFERROR(IF(F39<C39,"⚡ Cambiar proveedor","✅ OK"),"—") -> ✅ OK
A40: Crema Ledevit | B40: 4,7 l | C40: 35750 | F40: =IFERROR(MIN(C40,IF(D40<>"",D40,C40),IF(E40<>"",E40,C40)),"—") -> 35750 | G40: =IFERROR(C40-F40,"—") -> 0 | H40: =IFERROR((C40-F40)/C40,"—") -> 0 | I40: =IFERROR(IF(F40<C40,"⚡ Cambiar proveedor","✅ OK"),"—") -> ✅ OK
A41: Queso Cremoso | B41: 1 kg | C41: 5900 | F41: =IFERROR(MIN(C41,IF(D41<>"",D41,C41),IF(E41<>"",E41,C41)),"—") -> 5900 | G41: =IFERROR(C41-F41,"—") -> 0 | H41: =IFERROR((C41-F41)/C41,"—") -> 0 | I41: =IFERROR(IF(F41<C41,"⚡ Cambiar proveedor","✅ OK"),"—") -> ✅ OK
A42: Queso Tybo | B42: 1 kg | C42: 8676 | F42: =IFERROR(MIN(C42,IF(D42<>"",D42,C42),IF(E42<>"",E42,C42)),"—") -> 8676 | G42: =IFERROR(C42-F42,"—") -> 0 | H42: =IFERROR((C42-F42)/C42,"—") -> 0 | I42: =IFERROR(IF(F42<C42,"⚡ Cambiar proveedor","✅ OK"),"—") -> ✅ OK
A43: Dulce de Leche | B43: 10 kg | C43: 14625 | F43: =IFERROR(MIN(C43,IF(D43<>"",D43,C43),IF(E43<>"",E43,C43)),"—") -> 14625 | G43: =IFERROR(C43-F43,"—") -> 0 | H43: =IFERROR((C43-F43)/C43,"—") -> 0 | I43: =IFERROR(IF(F43<C43,"⚡ Cambiar proveedor","✅ OK"),"—") -> ✅ OK
A44: Harina de Arroz | B44: 25 kg | C44: 25000 | F44: =IFERROR(MIN(C44,IF(D44<>"",D44,C44),IF(E44<>"",E44,C44)),"—") -> 25000 | G44: =IFERROR(C44-F44,"—") -> 0 | H44: =IFERROR((C44-F44)/C44,"—") -> 0 | I44: =IFERROR(IF(F44<C44,"⚡ Cambiar proveedor","✅ OK"),"—") -> ✅ OK
A45: Goma Xántica | B45: 1 kg | C45: 11000 | F45: =IFERROR(MIN(C45,IF(D45<>"",D45,C45),IF(E45<>"",E45,C45)),"—") -> 11000 | G45: =IFERROR(C45-F45,"—") -> 0 | H45: =IFERROR((C45-F45)/C45,"—") -> 0 | I45: =IFERROR(IF(F45<C45,"⚡ Cambiar proveedor","✅ OK"),"—") -> ✅ OK
A48: 📒 SECCIÓN 3 — DIRECTORIO DE PROVEEDORES
A49: Proveedor | B49: Insumos que vende | C49: Contacto / Tel | D49: Zona / Dirección | E49: Forma de pago | F49: Entrega | G49: Calificación (1-5) | H49: Última compra | I49: Notas
A50: Frenart | B50: Almidón/Harina de Mandioca, Chocolate Semiamargo Coverlux | C50: — | D50: Pellegrini 473, La Banda | E50: Contado | F50: Retiro | G50: ⭐⭐⭐⭐ | H50: 28/02/2026 | I50: Proveedor actual mandioca y chocolate. Ticket 28/02/2026
A51: Ledevit | B51: Crema de leche | C51: — | D51: — | E51: — | F51: — | G51: — | H51: — | I51: Proveedor actual crema
A52: Distribuidora VIDT S.R.L. | B52: Jamón / Fiambres, Lácteos (manteca, quesos, crema) | C52: — | D52: Aristóbulo del Valle 466, La Banda | E52: Débito / Contado | F52: Retiro | G52: ⭐⭐⭐⭐ | H52: 28/02/2026 | I52: Lácteos a buenos precios. Descuento mayorista aplicado.
A53: Ridolfo Hnos. | B53: Almidón de Maíz, Chocolates (proveedor anterior) | C53: (0385) 427-1180 / 427-1515 | D53: Pellegrini 799, La Banda | E53: — | F53: — | G53: — | H53: — | I53: Proveedor anterior para almidón y chocolates. Comparar precios.
A54: Lactiband S.A. | B54: Lácteos (manteca, quesos, crema) — a consultar | C54: (0385) 427-2700 | D54: Av. Besares Sur 1087, La Banda | E54: — | F54: — | G54: — | H54: — | I54: Especialista en lácteos. Potencial alternativa a VIDT. Consultar precios.
A72: ⚡ Tip: Completá la Sección 2 con precios de otros proveedores para ver automáticamente cuánto podés ahorrar.

Sheet Proyección Semanal
A1: 📊 PROYECCIÓN SEMANAL DE VENTAS
A2: Celdas AMARILLAS = editables. Costos vinculados dinámicamente a Materias Primas.
A3: Producto | B3: Unidades Semanales | C3: Costo x Unidad ($) | D3: Costo Total ($) | E3: Precio Venta ($) | F3: Ingreso Total ($) | G3: Ganancia Bruta ($) | H3: Margen (%)
A4: 🍕 Prepizza | B4: 10 | C4: ='Recetas y Márgenes'!E51 -> 583.24598 | D4: =B4*C4 -> 5832.4598 | E4: 4000 | F4: =B4*E4 -> 40000 | G4: =F4-D4 -> 34167.54 | H4: =IFERROR(G4/F4,0) -> 0.8541885
A5: 🍫 Cabsha | B5: 15 | C5: ='Recetas y Márgenes'!E110 -> 341.8773 | D5: =B5*C5 -> 5128.1595 | E5: 2500 | F5: =B5*E5 -> 37500 | G5: =F5-D5 -> 32371.84 | H5: =IFERROR(G5/F5,0) -> 0.86324908
A6: 🥧 Pastafrola | B6: 15 | C6: ='Recetas y Márgenes'!E103 -> 314.65774 | D6: =B6*C6 -> 4719.8661 | E6: 2500 | F6: =B6*E6 -> 37500 | G6: =F6-D6 -> 32780.134 | H6: =IFERROR(G6/F6,0) -> 0.87413691
A7: 🍪 Cookie Crumbl Oreo | B7: 36 | C7: ='Recetas y Márgenes'!E77 -> 579.28029 | D7: =B7*C7 -> 20854.09 | E7: 2500 | F7: =B7*E7 -> 90000 | G7: =F7-D7 -> 69145.91 | H7: =IFERROR(G7/F7,0) -> 0.76828788
A8: 🍫 Brownie (porción) | B8: 24 | C8: ='Recetas y Márgenes'!E88 -> 749.21174 | D8: =B8*C8 -> 17981.082 | E8: 2500 | F8: =B8*E8 -> 60000 | G8: =F8-D8 -> 42018.918 | H8: =IFERROR(G8/F8,0) -> 0.7003153
A9: 🍰 Budín (porción) | B9: 12 | C9: ='Recetas y Márgenes'!E154 -> 485.39117 | D9: =B9*C9 -> 5824.6941 | E9: 2500 | F9: =B9*E9 -> 30000 | G9: =F9-D9 -> 24175.306 | H9: =IFERROR(G9/F9,0) -> 0.80584353
A10: 🍞 Pan de Molde | B10: 40 | C10: ='Recetas y Márgenes'!E10 -> 1270.165 | D10: =B10*C10 -> 50806.598 | E10: 6000 | F10: =B10*E10 -> 240000 | G10: =F10-D10 -> 189193.4 | H10: =IFERROR(G10/F10,0) -> 0.78830584
A11: 🥟 Empanadas | B11: 96 | C11: ='Recetas y Márgenes'!E40 -> 350.02208 | D11: =B11*C11 -> 33602.12 | E11: 1000 | F11: =B11*E11 -> 96000 | G11: =F11-D11 -> 62397.88 | H11: =IFERROR(G11/F11,0) -> 0.64997792
A12: 🥧 Tartas Saladas | B12: 10 | C12: ='Recetas y Márgenes'!E31 -> 987.18984 | D12: =B12*C12 -> 9871.8984 | E12: 8500 | F12: =B12*E12 -> 85000 | G12: =F12-D12 -> 75128.102 | H12: =IFERROR(G12/F12,0) -> 0.88386002
A13: 🥧 Tartas de Almendras | B13: 14 | C13: ='Recetas y Márgenes'!E20 -> 300.4353 | D13: =B13*C13 -> 4206.0942 | E13: 3000 | F13: =B13*E13 -> 42000 | G13: =F13-D13 -> 37793.906 | H13: =IFERROR(G13/F13,0) -> 0.8998549
A14: 🫓 Chipa (x100g) | B14: 40 | C14: ='Recetas y Márgenes'!E119 -> 571.0576 | D14: =B14*C14 -> 22842.304 | E14: 1500 | F14: =B14*E14 -> 60000 | G14: =F14-D14 -> 37157.696 | H14: =IFERROR(G14/F14,0) -> 0.61929493
A15: 🎂 Torta 2kg | B15: 1 | C15: ='Recetas y Márgenes'!E135 -> 8989.1532 | D15: =B15*C15 -> 8989.1532 | E15: 36000 | F15: =B15*E15 -> 36000 | G15: =F15-D15 -> 27010.847 | H15: =IFERROR(G15/F15,0) -> 0.7503013
A16: 🍪 Alfajores de Maicena | B16: 60 | C16: ='Recetas y Márgenes'!E165 -> 154.4001 | D16: =B16*C16 -> 9264.006 | E16: 800 | F16: =B16*E16 -> 48000 | G16: =F16-D16 -> 38735.994 | H16: =IFERROR(G16/F16,0) -> 0.80699988
A17: 🍗 Mila de Pollo (x kg) | B17: 10 | C17: ='Recetas y Márgenes'!D175 -> 7658.5586 | D17: =B17*C17 -> 76585.586 | E17: 14000 | F17: =B17*E17 -> 140000 | G17: =F17-D17 -> 63414.414 | H17: =IFERROR(G17/F17,0) -> 0.4529601
A18: 🫔 Canelones J&Q (porc. 3u) | B18: 8 | C18: ='Recetas y Márgenes'!D192 -> 1552.1286 | D18: =B18*C18 -> 12417.029 | E18: 6000 | F18: =B18*E18 -> 48000 | G18: =F18-D18 -> 35582.971 | H18: =IFERROR(G18/F18,0) -> 0.7413119
A19: 🥬 Canelones Verdura (porc. 3u) | B19: 7 | C19: ='Recetas y Márgenes'!D205 -> 1493.5595 | D19: =B19*C19 -> 10454.917 | E19: 6000 | F19: =B19*E19 -> 42000 | G19: =F19-D19 -> 31545.083 | H19: =IFERROR(G19/F19,0) -> 0.75107341
A20: 🍔 Pan de Hamburguesa (pack 4u) | B20: 12 | C20: ='Recetas y Márgenes'!D225 -> 462.16128 | D20: =B20*C20 -> 5545.9354 | E20: 5000 | F20: =B20*E20 -> 60000 | G20: =F20-D20 -> 54454.065 | H20: =IFERROR(G20/F20,0) -> 0.90756774
A21: 📦 TOTALES SEMANALES | B21: =SUM(B4:B20) -> 410 | D21: =SUM(D4:D20) -> 304925.99 | F21: =SUM(F4:F20) -> 1192000 | G21: =SUM(G4:G20) -> 887074.01 | H21: =IFERROR(G21/F21,0) -> 0.7441896
A23: 📈 RESUMEN DE KPIs
A24: 💰 Ingreso semanal total | E24: =F21 -> 1192000
A25: 💸 Costo semanal total | E25: =D21 -> 304925.99
A26: 📈 Ganancia bruta semanal | E26: =G21 -> 887074.01
A27: 📊 Margen bruto promedio | E27: =IFERROR(G21/F21,0) -> 0.7441896
A28: 📅 Proyección mensual (x4) | E28: =G21*4 -> 3548296
A29: 📅 Proyección anual (x52) | E29: =G21*52 -> 46127848
A31: 💼 GANANCIA NETA (descontando gastos fijos)
A32: ✅ Ganancia bruta semanal | E32: =G20 -> 54454.065
A33: 💼 Gastos fijos semanales | E33: ='Gastos Fijos'!D14 -> 2500
A34: 🏆 GANANCIA NETA SEMANAL | E34: =G20-'Gastos Fijos'!D14 -> 51954.065
A35: 📅 Ganancia neta mensual
A36: ⚡ Tip: Modificá las celdas en AMARILLO para simular distintos escenarios.

Sheet Stickers
A1: COSTO DE STICKERS
A2: Sticker | B2: Cantidad | C2: Costo Unitario ($)
A3: Sticker 1 | B3: 70 | C3: =16000/SUM(B3:B10) -> 54.607509
A4: Sticker 2 | B4: 32 | C4: =16000/SUM(B3:B10) -> 54.607509
A5: Sticker 3 | B5: 18 | C5: =16000/SUM(B3:B10) -> 54.607509
A6: Sticker 4 | B6: 11 | C6: =16000/SUM(B3:B10) -> 54.607509
A7: Sticker 5 | B7: 17 | C7: =16000/SUM(B3:B10) -> 54.607509
A8: Sticker 6 | B8: 61 | C8: =16000/SUM(B3:B10) -> 54.607509
A9: Sticker 7 | B9: 24 | C9: =16000/SUM(B3:B10) -> 54.607509
A10: Sticker 8 | B10: 60 | C10: =16000/SUM(B3:B10) -> 54.607509
A11: TOTAL: 293 unidades | B11: 293 | C11: 54.607509
